Workbook
Name IQ_CH: 110000
Name IQ_CQ: 5000
Name IQ_CY: 10000
Name IQ_DAILY: 500000
Name IQ_FH: 100000
Name IQ_FQ: 500
Name IQ_FY: 1000
Name IQ_LTM: 2000
Name IQ_MONTH: 15000
Name IQ_NTM: 6000
Name IQ_WEEK: 50000
Name IQ_YTD: 3000

Sheet Completion Factors
A1: Paid Percentages
E3: 3 month | F3: 6 month | G3: 12 month | I3: Selected | J3: Cumulative
A4: MONTH | B4: 3-month | C4: 6-month | D4: 12-month | E4: Cumulat | F4: Cumulat | G4: Cumulat | H4: Selected | I4: Cumulative | J4: Pd Pct
A5: OF LAG | B5: average | C5: average | D5: average | E5: Pd Pct | F5: Pd Pct | G5: Pd Pct | I5: Pd Pct | J5: used
A6: --------- | B6: ---------- | C6: ---------- | D6: ---------- | E6: ---------- | F6: ---------- | G6: ---------- | H6: ---------- | I6: ---------- | J6: ----------
A7: 0 | B7: =+E7/E8 | C7: =+F7/F8 | D7: =+G7/G8 | E7: 0.12572812 | F7: 0.069959798 | G7: 0.06214402 | H7: =+I7/I8 | I7: 0.089897363 | J7: =I7
A8: =1+A7 | B8: =+E8/E9 | C8: =+F8/F9 | D8: =+G8/G9 | E8: 0.90903827 | F8: 0.80957175 | G8: 0.57650822 | H8: =+I8/I9 | I8: 0.85642664 | J8: =I8
A9: =1+A8 | B9: =+E9/E10 | C9: =+F9/F10 | D9: =+G9/G10 | E9: 0.94502403 | F9: 0.94042619 | G9: 0.68603948 | H9: =+I9/I10 | I9: 0.9427195 | J9: =I9
A10: =1+A9 | B10: =+E10/E11 | C10: =+F10/F11 | D10: =+G10/G11 | E10: 0.98537571 | F10: 0.9808531 | G10: 0.85812275 | H10: =+I10/I11 | I10: 0.9831092 | J10: =I10
A11: =1+A10 | B11: =+E11/E12 | C11: =+F11/F12 | D11: =+G11/G12 | E11: 0.98537571 | F11: 0.99232268 | G11: 0.97497175 | H11: =+I11/I12 | I11: 0.98883699 | J11: =I11
A12: =1+A11 | B12: =+E12/E13 | C12: =+F12/F13 | D12: =+G12/G13 | E12: 1 | F12: 0.99888521 | G12: 0.99247032 | H12: =+I12/I13 | I12: 0.99944229 | J12: =I12
A13: =1+A12 | B13: =+E13/E14 | C13: =+F13/F14 | D13: =+G13/G14 | E13: 1 | F13: 0.99888521 | G13: 0.99520761 | H13: =+I13/I14 | I13: 0.99944229 | J13: =I13
A14: =1+A13 | B14: =+E14/E15 | C14: =+F14/F15 | D14: =+G14/G15 | E14: 1 | F14: 0.99888521 | G14: 0.99834258 | H14: =+I14/I15 | I14: 0.99944229 | J14: =I14
A15: =1+A14 | B15: =+E15/E16 | C15: =+F15/F16 | D15: =+G15/G16 | E15: 1 | F15: 1 | G15: 0.9991698 | H15: =+I15/I16 | I15: 1 | J15: =I15
A16: =1+A15 | B16: =+E16/E17 | C16: =+F16/F17 | D16: =+G16/G17 | E16: 1 | F16: 1 | G16: 1 | H16: =+I16/I17 | I16: 1 | J16: =I16
A17: =1+A16 | B17: =+E17/E18 | C17: =+F17/F18 | D17: =+G17/G18 | E17: 1 | F17: 1 | G17: 1 | H17: =+I17/I18 | I17: 1 | J17: =I17
A18: =1+A17 | B18: =+E18/E19 | C18: =+F18/F19 | D18: =+G18/G19 | E18: 1 | F18: 1 | G18: 1 | H18: =+I18/I19 | I18: 1 | J18: =I18
A19: =1+A18 | B19: =+E19/E20 | C19: =+F19/F20 | D19: =+G19/G20 | E19: 1 | F19: 1 | G19: 1 | H19: =+I19/I20 | I19: 1 | J19: =I19
... A29: =1+A28 | B29: =+E29/E30 | C29: =+F29/F30 | D29: =+G29/G30 | E29: 1 | F29: 1 | G29: 1 | H29: =+I29/I30 | I29: 1 | J29: =I29
A30: 23 | B30: 1 | C30: 1 | D30: 1 | E30: 1 | F30: 1 | G30: 1 | H30: 1 | I30: 1 | J30: =I30
E34: LINK RATIOS
A35: Accident
A36: Month | B36: Month of Lag
A37: ------ | B37: --- | C37: --- | D37: --- | E37: --- | F37: --- | G37: --- | H37: --- | I37: --- | J37: --- | K37: --- | L37: --- | M37: --- | N37: --- | O37: --- | P37: --- | Q37: --- | R37: --- | S37: --- | T37: --- | U37: --- | V37: --- | W37: --- | X37: ---
A38: 0 | C38: 1.1177084 | D38: 1 | E38: 1 | F38: 1 | G38: 1 | H38: 1 | I38: 1 | J38: 1 | K38: 1 | L38: 1 | M38: 1 | N38: 1 | O38: 1 | P38: 1 | Q38: 1 | R38: 1 | S38: 1 | T38: 1 | U38: 1 | V38: 1 | W38: 1 | X38: 1
A39: =1+A38 | B39: 2.1170646 | C39: 1.6225585 | D39: 1 | E39: 1 | F39: 1 | G39: 1 | H39: 1 | I39: 1 | J39: 1 | K39: 1 | L39: 1 | M39: 1 | N39: 1 | O39: 1 | P39: 1 | Q39: 1 | R39: 1 | S39: 1 | T39: 1 | U39: 1 | V39: 1 | W39: 1
A40: =1+A39 | C40: 1 | D40: 1.0565144 | E40: 1 | F40: 0.85487425 | G40: 1 | H40: 1 | I40: 1 | J40: 1 | K40: 1 | L40: 1 | M40: 1 | N40: 1 | O40: 1 | P40: 1 | Q40: 1 | R40: 1 | S40: 1 | T40: 1 | U40: 1 | V40: 1
A41: =1+A40 | B41: 15.376364 | C41: 1.2273265 | D41: 1 | E41: 1 | F41: 1 | G41: 1 | H41: 1 | I41: 1 | J41: 1 | K41: 1 | L41: 1 | M41: 1 | N41: 1 | O41: 1 | P41: 1 | Q41: 1 | R41: 1 | S41: 1 | T41: 1 | U41: 1
A42: =1+A41 | C42: 1.2287655 | D42: 2.8906583 | E42: 1 | F42: 1 | G42: 1 | H42: 1 | I42: 1 | J42: 1 | K42: 1 | L42: 1 | M42: 1 | N42: 1 | O42: 1 | P42: 1 | Q42: 1 | R42: 1 | S42: 1 | T42: 1
A43: =1+A42 | C43: 1 | D43: 1 | E43: 1 | F43: 1 | G43: 1 | H43: 1 | I43: 1 | J43: 1 | K43: 1 | L43: 1 | M43: 1 | N43: 1 | O43: 1 | P43: 1 | Q43: 1 | R43: 1 | S43: 1
A44: =1+A43 | B44: 5.3754672 | C44: 1 | D44: 1 | E44: 1 | F44: 1.0341815 | G44: 1 | H44: 1 | I44: 1 | J44: 1.0061364 | K44: 1 | L44: 1 | M44: 1 | N44: 1 | O44: 1 | P44: 1 | Q44: 1 | R44: 1
A45: =1+A44 | F45: 2.1858924 | G45: 1 | H45: 1 | I45: 1 | J45: 1 | K45: 1 | L45: 1 | M45: 1 | N45: 1 | O45: 1 | P45: 1 | Q45: 1
A46: =1+A45 | E46: 1 | F46: 1 | G46: 1 | H46: 1 | I46: 1 | J46: 1 | K46: 1 | L46: 1 | M46: 1 | N46: 1 | O46: 1 | P46: 1
A47: =1+A46 | D47: 1.078156 | E47: 1 | F47: 1 | G47: 1.0360153 | H47: 1 | I47: 1 | J47: 1 | K47: 1 | L47: 1 | M47: 1 | N47: 1 | O47: 1
A48: =1+A47 | C48: 1.3244526 | D48: 2.9852525 | E48: 1 | F48: 1.003748 | G48: 1 | H48: 1.0136409 | I48: 1 | J48: 1 | K48: 1 | L48: 1 | M48: 1 | N48: 1
A49: =1+A48 | B49: 2.6851698 | C49: 1.322796 | D49: 2.2322568 | E49: 1 | F49: 1 | G49: 1.019673 | H49: 1 | I49: 1 | J49: 1 | K49: 1 | L49: 1 | M49: 1
A50: =1+A49 | B50: 2.5352925 | C50: 2.348283 | D50: 1.3188172 | E50: 1 | F50: 1.134462 | G50: 1 | H50: 1 | I50: 1.0289837 | J50: 1 | K50: 1 | L50: 1
A51: =1+A50 | B51: 119.33687 | C51: 1.318104 | D51: 1.0148394 | E51: 2.3806402 | F51: 1 | G51: 1 | H51: 1 | I51: 1 | J51: 1 | K51: 1
A52: =1+A51 | B52: 9.6346635 | C52: 1 | D52: 1.0343943 | E52: 1.0673335 | F52: 1 | G52: 1 | H52: 1 | I52: 1 | J52: 1
A53: =1+A52 | B53: 2.4506444 | C53: 1.440787 | D53: 1.0639011 | E53: 1 | F53: 1.0024219 | G53: 1 | H53: 1 | I53: 1
...

Sheet Plot Patterns
A1: Cumulative Development | B1: Volume All | C1: Volume 12 | D1: Volume 6 | E1: Volume 3 | F1: Simple All | G1: Simple 12 | H1: Simple 6 | I1: Simple 3 | J1: Selected | M1: Incremental Pattern | N1: Volume All | O1: Volume 12 | P1: Volume 6 | Q1: Volume 3 | R1: Simple All | S1: Simple 12 | T1: Simple 6 | U1: Simple 3 | V1: Selected
A2: 1 | B2: 0.07636291 | C2: 0.06214402 | D2: 0.069959798 | E2: 0.12572812 | F2: 0.029702253 | G2: 0.021763216 | H2: 0.060815558 | I2: 0.075296143 | J2: 0.089897363 | M2: 1 | N2: 8.0159707 | O2: 9.2769701 | P2: 11.571957 | Q2: 7.2301903 | R2: 17.840136 | S2: 21.245859 | T2: 13.642523 | U2: 12.113603 | V2: 9.4010735
A3: =+A2+1 | B3: 0.61212285 | C3: 0.57650822 | D3: 0.80957175 | E3: 0.90903827 | F3: 0.52989222 | G3: 0.46237822 | H3: 0.82967763 | I3: 0.91210754 | J3: 0.85642664 | M3: =+M2+1 | N3: 1.1637977 | O3: 1.1899908 | P3: 1.1616342 | Q3: 1.0395866 | R3: 1.25263 | S3: 1.300301 | T3: 1.1415315 | U3: 1.0598955 | V3: 1.1006104
A4: =+A3+1 | B4: 0.71238714 | C4: 0.68603948 | D4: 0.94042619 | E4: 0.94502403 | F4: 0.66375891 | G4: 0.60123085 | H4: 0.94710316 | I4: 0.9667387 | J4: 0.9427195 | M4: =+M3+1 | N4: 1.2333666 | O4: 1.2508358 | P4: 1.0429879 | Q4: 1.0426991 | R4: 1.306633 | S4: 1.3232379 | T4: 1.0358565 | U4: 1.0287656 | V4: 1.0428435
A5: =+A4+1 | B5: 0.87863453 | C5: 0.85812275 | D5: 0.9808531 | E5: 0.98537571 | F5: 0.86728933 | G5: 0.79557147 | H5: 0.98106297 | I5: 0.99454753 | J5: 0.9831092 | M5: =+M4+1 | N5: 1.1117379 | O5: 1.1361682 | P5: 1.0116935 | Q5: 1 | R5: 1.0762091 | S5: 1.1206645 | T5: 1.0112223 | U5: 1 | V5: 1.0058467
A6: =+A5+1 | B6: 0.97681134 | C6: 0.97497175 | D6: 0.99232268 | E6: 0.98537571 | F6: 0.9333847 | G6: 0.89156868 | H6: 0.9920727 | I6: 0.99454753 | J6: 0.98883699 | M6: =+M5+1 | N6: 1.0167089 | O6: 1.0179478 | P6: 1.0066133 | Q6: 1.0148413 | R6: 1.0648435 | S6: 1.1119143 | T6: 1.0031448 | U6: 1.0054824 | V6: 1.0107273
A7: =+A6+1 | B7: 0.99313275 | C7: 0.99247032 | D7: 0.99888521 | E7: 1 | F7: 0.99390867 | G7: 0.99134795 | H7: 0.9951926 | I7: 1 | J7: 0.99944229 | M7: =+M6+1 | N7: 1.0024634 | O7: 1.0027581 | P7: 1 | Q7: 1 | R7: 1.0030938 | S7: 1.0046407 | T7: 1 | U7: 1 | V7: 1
A8: =+A7+1 | B8: 0.99557927 | C8: 0.99520761 | D8: 0.99888521 | E8: 1 | F8: 0.99698362 | G8: 0.9959485 | H8: 0.9951926 | I8: 1 | J8: 0.99944229 | M8: =+M7+1 | N8: 1.002845 | O8: 1.0031501 | P8: 1 | Q8: 1 | R8: 1.0008024 | S8: 1.0011367 | T8: 1 | U8: 1 | V8: 1
A9: =+A8+1 | B9: 0.99841173 | C9: 0.99834258 | D9: 0.99888521 | E9: 1 | F9: 0.99778361 | G9: 0.99708063 | H9: 0.9951926 | I9: 1 | J9: 0.99944229 | M9: =+M8+1 | N9: 1.000787 | O9: 1.0008286 | P9: 1.001116 | Q9: 1 | R9: 1.0018115 | S9: 1.0024153 | T9: 1.0048306 | U9: 1 | V9: 1.000558
A10: =+A9+1 | B10: 0.99919753 | C10: 0.9991698 | D10: 1 | E10: 1 | F10: 0.99959107 | G10: 0.99948889 | H10: 1 | I10: 1 | J10: 1 | M10: =+M9+1 | N10: 1.0008031 | O10: 1.0008309 | P10: 1 | Q10: 1 | R10: 1.0004091 | S10: 1.0005114 | T10: 1 | U10: 1 | V10: 1
A11: =+A10+1 | B11: 1 | C11: 1 | D11: 1 | E11: 1 | F11: 1 | G11: 1 | H11: 1 | I11: 1 | J11: 1 | M11: =+M10+1 | N11: 1 | O11: 1 | P11: 1 | Q11: 1 | R11: 1 | S11: 1 | T11: 1 | U11: 1 | V11: 1
A12: =+A11+1 | B12: 1 | C12: 1 | D12: 1 | E12: 1 | F12: 1 | G12: 1 | H12: 1 | I12: 1 | J12: 1 | M12: =+M11+1 | N12: 1 | O12: 1 | P12: 1 | Q12: 1 | R12: 1 | S12: 1 | T12: 1 | U12: 1 | V12: 1
A13: =+A12+1 | B13: 1 | C13: 1 | D13: 1 | E13: 1 | F13: 1 | G13: 1 | H13: 1 | I13: 1 | J13: 1 | M13: =+M12+1 | N13: 1 | O13: 1 | P13: 1 | Q13: 1 | R13: 1 | S13: 1 | T13: 1 | U13: 1 | V13: 1
A14: =+A13+1 | B14: 1 | C14: 1 | D14: 1 | E14: 1 | F14: 1 | G14: 1 | H14: 1 | I14: 1 | J14: 1 | M14: =+M13+1 | N14: 1 | O14: 1 | P14: 1 | Q14: 1 | R14: 1 | S14: 1 | T14: 1 | U14: 1 | V14: 1
... A24: =+A23+1 | B24: 1 | C24: 1 | D24: 1 | E24: 1 | F24: 1 | G24: 1 | H24: 1 | I24: 1 | J24: 1 | M24: =+M23+1 | N24: 1 | O24: 1 | P24: 1 | Q24: 1 | R24: 1 | S24: 1 | T24: 1 | U24: 1 | V24: 1

Sheet Summary
D4: Raw | E4: Total | F4: Adjustment | G4: Projected | H4: 45838 | J4: LOSS RATIO
A5: Incurral | B5: Claims | C5: Paid % | D5: Claim | E5: Claim | F5: to Claim | G5: Incurred | H5: Claim | L5: Incurred | M5: Latest
A6: Month | B6: Paid | C6: (Cum) | D6: Liability | E6: Liability | F6: Liability | G6: Claims | H6: Liability | I6: Premiums | J6: Incurred | K6: Paid | L6: less Pd | M6: 12 Mos. | S6: Paid Month | AR6: Paid
A7: ----- | B7: ---- | C7: ----- | D7: --------- | E7: --------- | F7: --------- | G7: ----- | H7: --------- | I7: -------- | J7: -------- | K7: ---- | L7: -------- | M7: ------- | R7: Incurral Month | S7: =R8 | T7: =R9 | U7: =R10 | V7: =R11 | W7: =R12 | X7: =R13 | Y7: =R14 | Z7: =R15 | AA7: =R16 | AB7: =R17 | AC7: =R18 | AD7: =R19 | AE7: =R20 | AF7: =R21 | AG7: =R22 | AH7: =R23 | AI7: =R24 | AJ7: =R25 | AK7: =R26 | AL7: =R27 | AM7: =R28 | AN7: =R29 | AO7: =R30 | AP7: =R31 | AQ7: Total | AR7: Total
A8: =DATE(YEAR(A9),MONTH(A9)-1,1) | B8: 160.76 | C8: =+'Completion Factors'!J30 | D8: =MAX((1/C8-1)*B8,0) | E8: =D8 | G8: =B8+D8+F8 | H8: =G8-B8 | I8: 1976.4033 | J8: =100*$G8/$I8 | K8: =100*(B8/I8) | L8: =J8-K8 | R8: =A8 | T8: 143.83 | U8: 160.76 | V8: 160.76 | W8: 160.76 | X8: 160.76 | Y8: 160.76 | Z8: 160.76 | AA8: 160.76 | AB8: 160.76 | AC8: 160.76 | AD8: 160.76 | AE8: 160.76 | AF8: 160.76 | AG8: 160.76 | AH8: 160.76 | AI8: 160.76 | AJ8: 160.76 | AK8: 160.76 | AL8: 160.76 | AM8: 160.76 | AN8: 160.76 | AO8: 160.76 | AP8: 160.76
A9: =DATE(YEAR(A10),MONTH(A10)-1,1) | B9: 117.96 | C9: =+'Completion Factors'!J29 | D9: =MAX((1/C9-1)*B9,0) | E9: =D9 | G9: =B9+D9+F9 | H9: =G9-B9 | I9: 1976.4033 | J9: =100*$G9/$I9 | K9: =100*(B9/I9) | L9: =J9-K9 | R9: =A9 | S9: 34.34 | T9: 72.7 | U9: 117.96 | V9: 117.96 | W9: 117.96 | X9: 117.96 | Y9: 117.96 | Z9: 117.96 | AA9: 117.96 | AB9: 117.96 | AC9: 117.96 | AD9: 117.96 | AE9: 117.96 | AF9: 117.96 | AG9: 117.96 | AH9: 117.96 | AI9: 117.96 | AJ9: 117.96 | AK9: 117.96 | AL9: 117.96 | AM9: 117.96 | AN9: 117.96 | AO9: 117.96
A10: =DATE(YEAR(A11),MONTH(A11)-1,1) | B10: 112.51 | C10: =+'Completion Factors'!J28 | D10: =MAX((1/C10-1)*B10,0) | E10: =D10 | G10: =B10+D10+F10 | H10: =G10-B10 | I10: 1976.4033 | J10: =100*$G10/$I10 | K10: =100*(B10/I10) | L10: =J10-K10 | R10: =A10 | T10: 124.57 | U10: 124.57 | V10: 131.61 | W10: 131.61 | X10: 112.51 | Y10: 112.51 | Z10: 112.51 | AA10: 112.51 | AB10: 112.51 | AC10: 112.51 | AD10: 112.51 | AE10: 112.51 | AF10: 112.51 | AG10: 112.51 | AH10: 112.51 | AI10: 112.51 | AJ10: 112.51 | AK10: 112.51 | AL10: 112.51 | AM10: 112.51 | AN10: 112.51
A11: =DATE(YEAR(A12),MONTH(A12)-1,1) | B11: 207.59 | C11: =+'Completion Factors'!J27 | D11: =MAX((1/C11-1)*B11,0) | E11: =D11 | G11: =B11+D11+F11 | H11: =G11-B11 | I11: 1976.4033 | J11: =100*$G11/$I11 | K11: =100*(B11/I11) | L11: =J11-K11 | R11: =A11 | S11: 11 | T11: 169.14 | U11: 207.59 | V11: 207.59 | W11: 207.59 | X11: 207.59 | Y11: 207.59 | Z11: 207.59 | AA11: 207.59 | AB11: 207.59 | AC11: 207.59 | AD11: 207.59 | AE11: 207.59 | AF11: 207.59 | AG11: 207.59 | AH11: 207.59 | AI11: 207.59 | AJ11: 207.59 | AK11: 207.59 | AL11: 207.59 | AM11: 207.59
A12: =DATE(YEAR(A13),MONTH(A13)-1,1) | B12: 569.98 | C12: =++'Completion Factors'!J26 | D12: =MAX((1/C12-1)*B12,0) | E12: =D12 | G12: =B12+D12+F12 | H12: =G12-B12 | I12: 1722.4033 | J12: =100*$G12/$I12 | K12: =100*(B12/I12) | L12: =J12-K12 | R12: =A12 | T12: 160.47 | U12: 197.18 | V12: 569.98 | W12: 569.98 | X12: 569.98 | Y12: 569.98 | Z12: 569.98 | AA12: 569.98 | AB12: 569.98 | AC12: 569.98 | AD12: 569.98 | AE12: 569.98 | AF12: 569.98 | AG12: 569.98 | AH12: 569.98 | AI12: 569.98 | AJ12: 569.98 | AK12: 569.98 | AL12: 569.98
A13: =DATE(YEAR(A14),MONTH(A14)-1,1) | B13: 136.83 | C13: =++'Completion Factors'!J25 | D13: =MAX((1/C13-1)*B13,0) | E13: =D13 | G13: =B13+D13+F13 | H13: =G13-B13 | I13: 1722.4033 | J13: =100*$G13/$I13 | K13: =100*(B13/I13) | L13: =J13-K13 | R13: =A13 | T13: 136.83 | U13: 136.83 | V13: 136.83 | W13: 136.83 | X13: 136.83 | Y13: 136.83 | Z13: 136.83 | AA13: 136.83 | AB13: 136.83 | AC13: 136.83 | AD13: 136.83 | AE13: 136.83 | AF13: 136.83 | AG13: 136.83 | AH13: 136.83 | AI13: 136.83 | AJ13: 136.83 | AK13: 136.83
A14: =DATE(YEAR(A15),MONTH(A15)-1,1) | B14: 1541.24 | C14: =++'Completion Factors'!J24 | D14: =MAX((1/C14-1)*B14,0) | E14: =D14 | G14: =B14+D14+F14 | H14: =G14-B14 | I14: 1722.4033 | J14: =100*$G14/$I14 | K14: =100*(B14/I14) | L14: =J14-K14 | R14: =A14 | S14: 275.55 | T14: 1481.21 | U14: 1481.21 | V14: 1481.21 | W14: 1481.21 | X14: 1531.84 | Y14: 1531.84 | Z14: 1531.84 | AA14: 1531.84 | AB14: 1541.24 | AC14: 1541.24 | AD14: 1541.24 | AE14: 1541.24 | AF14: 1541.24 | AG14: 1541.24 | AH14: 1541.24 | AI14: 1541.24 | AJ14: 1541.24
A15: =DATE(YEAR(A16),MONTH(A16)-1,1) | B15: 224.36 | C15: =++'Completion Factors'!J23 | D15: =MAX((1/C15-1)*B15,0) | E15: =D15 | G15: =B15+D15+F15 | H15: =G15-B15 | I15: 1722.4033 | J15: =100*$G15/$I15 | K15: =100*(B15/I15) | L15: =J15-K15 | R15: =A15 | W15: 102.64 | X15: 224.36 | Y15: 224.36 | Z15: 224.36 | AA15: 224.36 | AB15: 224.36 | AC15: 224.36 | AD15: 224.36 | AE15: 224.36 | AF15: 224.36 | AG15: 224.36 | AH15: 224.36 | AI15: 224.36
A16: =DATE(YEAR(A17),MONTH(A17)-1,1) | B16: 188.43 | C16: =++'Completion Factors'!J22 | D16: =MAX((1/C16-1)*B16,0) | E16: =D16 | G16: =B16+D16+F16 | H16: =G16-B16 | I16: 1722.4033 | J16: =100*$G16/$I16 | K16: =100*(B16/I16) | L16: =J16-K16 | R16: =A16 | V16: 188.43 | W16: 188.43 | X16: 188.43 | Y16: 188.43 | Z16: 188.43 | AA16: 188.43 | AB16: 188.43 | AC16: 188.43 | AD16: 188.43 | AE16: 188.43 | AF16: 188.43 | AG16: 188.43 | AH16: 188.43
A17: =DATE(YEAR(A18),MONTH(A18)-1,1) | B17: 270.4 | C17: =++'Completion Factors'!J21 | D17: =MAX((1/C17-1)*B17,0) | E17: =D17 | G17: =B17+D17+F17 | H17: =G17-B17 | I17: 1722.4033 | J17: =100*$G17/$I17 | K17: =100*(B17/I17) | L17: =J17-K17 | R17: =A17 | U17: 242.08 | V17: 261 | W17: 261 | X17: 261 | Y17: 270.4 | Z17: 270.4 | AA17: 270.4 | AB17: 270.4 | AC17: 270.4 | AD17: 270.4 | AE17: 270.4 | AF17: 270.4 | AG17: 270.4
A18: =DATE(YEAR(A19),MONTH(A19)-1,1) | B18: 2551.77 | C18: =++'Completion Factors'!J20 | D18: =MAX((1/C18-1)*B18,0) | E18: =D18 | G18: =B18+D18+F18 | H18: =G18-B18 | I18: 1716.74 | J18: =100*$G18/$I18 | K18: =100*(B18/I18) | L18: =J18-K18 | R18: =A18 | T18: 634.33 | U18: 840.14 | V18: 2508.03 | W18: 2508.03 | X18: 2517.43 | Y18: 2517.43 | Z18: 2551.77 | AA18: 2551.77 | AB18: 2551.77 | AC18: 2551.77 | AD18: 2551.77 | AE18: 2551.77 | AF18: 2551.77
A19: =DATE(YEAR(A20),MONTH(A20)-1,1) | B19: 1073.42 | C19: =++'Completion Factors'!J19 | D19: =MAX((1/C19-1)*B19,0) | E19: =D19 | G19: =B19+D19+F19 | H19: =G19-B19 | I19: 1716.74 | J19: =100*$G19/$I19 | K19: =100*(B19/I19) | L19: =J19-K19 | M19: =SUM(G8:G19)/SUM(I8:I19)*100 | R19: =A19 | S19: 132.77 | T19: 356.51 | U19: 471.59 | V19: 1052.71 | W19: 1052.71 | X19: 1052.71 | Y19: 1073.42 | Z19: 1073.42 | AA19: 1073.42 | AB19: 1073.42 | AC19: 1073.42 | AD19: 1073.42 | AE19: 1073.42
A20: =DATE(YEAR(A21),MONTH(A21)-1,1) | B20: 333.72 | C20: =++'Completion Factors'!J18 | D20: =MAX((1/C20-1)*B20,0) | E20: =D20 | G20: =B20+D20+F20 | H20: =G20-B20 | I20: 1716.74 | J20: =100*$G20/$I20 | K20: =100*(B20/I20) | L20: =J20-K20 | M20: =SUM(G9:G20)/SUM(I9:I20)*100 | N20: =J20/J8 | O20: =I20/I8 | R20: =A20 | S20: 36.41 | T20: 92.31 | U20: 216.77 | V20: 285.88 | W20: 285.88 | X20: 324.32 | Y20: 324.32 | Z20: 324.32 | AA20: 333.72 | AB20: 333.72 | AC20: 333.72 | AD20: 333.72
A21: =DATE(YEAR(A22),MONTH(A22)-1,1) | B21: 2865.41 | C21: =++'Completion Factors'!J17 | D21: =MAX((1/C21-1)*B21,0) | E21: =D21 | G21: =B21+D21+F21 | H21: =G21-B21 | I21: 1716.74 | J21: =100*$G21/$I21 | K21: =100*(B21/I21) | L21: =J21-K21 | M21: =SUM(G10:G21)/SUM(I10:I21)*100 | N21: =J21/J9 | O21: =I21/I9 | R21: =A21 | S21: 7.54 | T21: 899.8 | U21: 1186.03 | V21: 1203.63 | W21: 2865.41 | X21: 2865.41 | Y21: 2865.41 | Z21: 2865.41 | AA21: 2865.41 | AB21: 2865.41 | AC21: 2865.41
A22: =DATE(YEAR(A23),MONTH(A23)-1,1) | B22: 1359.42 | C22: =++'Completion Factors'!J16 | D22: =MAX((1/C22-1)*B22,0) | E22: =D22 | G22: =B22+D22+F22 | H22: =G22-B22 | I22: 1716.74 | J22: =100*$G22/$I22 | K22: =100*(B22/I22) | L22: =J22-K22 | M22: =SUM(G11:G22)/SUM(I11:I22)*100 | N22: =J22/J10 | O22: =I22/I10 | R22: =A22 | S22: 127.8 | T22: 1231.31 | U22: 1231.31 | V22: 1273.66 | W22: 1359.42 | X22: 1359.42 | Y22: 1359.42 | Z22: 1359.42 | AA22: 1359.42 | AB22: 1359.42
A23: =DATE(YEAR(A24),MONTH(A24)-1,1) | B23: 248.34 | C23: =++'Completion Factors'!J15 | D23: =MAX((1/C23-1)*B23,0) | E23: =D23 | G23: =B23+D23+F23 | H23: =G23-B23 | I23: 1716.74 | J23: =100*$G23/$I23 | K23: =100*(B23/I23) | L23: =J23-K23 | M23: =SUM(G12:G23)/SUM(I12:I23)*100 | N23: =J23/J11 | O23: =I23/I11 | R23: =A23 | S23: 65.95 | T23: 161.62 | U23: 232.86 | V23: 247.74 | W23: 247.74 | X23: 248.34 | Y23: 248.34 | Z23: 248.34 | AA23: 248.34
A24: =DATE(YEAR(A25),MONTH(A25)-1,1) | B24: 161.17 | C24: =++'Completion Factors'!J14 | D24: =MAX((1/C24-1)*B24,0) | E24: =D24 | F24: 0 | G24: =B24+D24+F24 | H24: =G24-B24 | I24: 1716.74 | J24: =100*$G24/$I24 | K24: =100*(B24/I24) | L24: =J24-K24 | M24: =SUM(G13:G24)/SUM(I13:I24)*100 | N24: =J24/J12 | O24: =I24/I12 | R24: =A24 | T24: 139.63 | U24: 161.17 | V24: 161.17 | W24: 161.17 | X24: 161.17 | Y24: 161.17 | Z24: 161.17
A25: =DATE(YEAR(A26),MONTH(A26)-1,1) | B25: 182.68 | C25: =++'Completion Factors'!J13 | D25: =MAX((1/C25-1)*B25,0) | E25: =D25 | F25: 0 | G25: =B25+D25+F25 | H25: =G25-B25 | I25: 1716.74 | J25: =100*$G25/$I25 | K25: =100*(B25/I25) | L25: =J25-K25 | M25: =SUM(G14:G25)/SUM(I14:I25)*100 | N25: =J25/J13 | O25: =I25/I13 | R25: =A25 | T25: 146.21 | U25: 171.54 | V25: 182.68 | W25: 182.68 | X25: 182.68 | Y25: 182.68
A26: =DATE(YEAR(A27),MONTH(A27)-1,1) | B26: 3230.34 | C26: =++'Completion Factors'!J12 | D26: =MAX((1/C26-1)*B26,0) | E26: =D26 | F26: 0 | G26: =B26+D26+F26 | H26: =G26-B26 | I26: 1716.74 | J26: =100*$G26/$I26 | K26: =100*(B26/I26) | L26: =J26-K26 | M26: =SUM(G15:G26)/SUM(I15:I26)*100 | N26: =J26/J14 | O26: =I26/I14 | R26: =A26 | S26: 119.59 | T26: 2180.04 | U26: 2925.6 | V26: 3178.07 | W26: 3178.07 | X26: 3230.34
A27: =DATE(YEAR(A28),MONTH(A28)-1,1) | B27: 2290.69 | C27: =++'Completion Factors'!J11 | D27: =MAX((1/C27-1)*B27,0) | E27: =D27 | F27: 0 | G27: =B27+D27+F27 | H27: =G27-B27 | I27: 1454.74 | J27: =100*$G27/$I27 | K27: =100*(B27/I27) | L27: =J27-K27 | M27: =SUM(G16:G27)/SUM(I16:I27)*100 | N27: =J27/J15 | O27: =I27/I15 | R27: =A27 | T27: 2262.79 | U27: 2290.69 | V27: 2290.69 | W27: 2290.69
A28: =DATE(YEAR(A29),MONTH(A29)-1,1) | B28: 696.48 | C28: =++'Completion Factors'!J10 | D28: =MAX((1/C28-1)*B28,0) | E28: =D28 | F28: 0 | G28: =B28+D28+F28 | H28: =G28-B28 | I28: 1454.74 | J28: =100*$G28/$I28 | K28: =100*(B28/I28) | L28: =J28-K28 | M28: =SUM(G17:G28)/SUM(I17:I28)*100 | N28: =J28/J16 | O28: =I28/I16 | R28: =A28 | S28: 22.06 | T28: 596.63 | U28: 696.48 | V28: 696.48
A29: =DATE(YEAR(A30),MONTH(A30)-1,1) | B29: 367.68 | C29: =++'Completion Factors'!J9 | D29: =MAX((1/C29-1)*B29,0) | E29: =D29 | F29: =ROUND(+I29*J29/100,0)-D29-B29 | G29: =B29+D29+F29 | H29: =G29-B29 | I29: 1451.2 | J29: 100 | K29: =100*(B29/I29) | L29: =J29-K29 | M29: =SUM(G18:G29)/SUM(I18:I29)*100 | N29: =J29/J17 | O29: =I29/I17 | R29: =A29 | S29: 67.64 | T29: 367.68 | U29: 367.68
A30: =DATE(YEAR(A31),MONTH(A31)-1,1) | B30: 361.49 | C30: =++'Completion Factors'!J8 | D30: =MAX((1/C30-1)*B30,0) | E30: =D30 | F30: =ROUND(+I30*J30/100,0)-D30-B30 | G30: =B30+D30+F30 | H30: =G30-B30 | I30: 1451.2 | J30: 70 | K30: =100*(B30/I30) | L30: =J30-K30 | M30: =SUM(G19:G30)/SUM(I19:I30)*100 | N30: =J30/J18 | O30: =I30/I18 | R30: =A30 | S30: 93.67 | T30: 361.49
A31: =DATE(YEAR(H4),MONTH(H4),1) | B31: 70.51 | C31: =+'Completion Factors'!J7 | D31: =MAX((1/C31-1)*B31,0) | E31: =D31 | F31: =ROUND(+I31*J31/100,0)-D31-B31 | G31: =B31+D31+F31 | H31: =G31-B31 | I31: 1451.2 | J31: 70 | K31: =100*(B31/I31) | L31: =J31-K31 | M31: =SUM(G20:G31)/SUM(I20:I31)*100 | N31: =J31/J19 | O31: =I31/I19 | R31: =A31 | S31: 70.51
H32: -------------- | R32: Total
H33: =SUM(H8:H31) | J33: =SUM(G20:G31)/SUM(I20:I31)
G34: =IF(ABS(+B33+E33+F33-G33)>0.005,B33+E33+F33," ")
H35: 0.075
H36: =H33*(1+H35)
